Workbook

Sheet Resumen
A1: RESUMEN DE METRADOS - CIMENTACIÓN Y COLUMNAS
A2: Vivienda unifamiliar 3 niveles - Chorrillos, Lima. Láminas E-01, E-02 (VE desde -1.50, mismo nivel que zapatas) y E-04. Precios unitarios en AMARILLO para llenar.
A4: Ítem | B4: Descripción | C4: Und | D4: Metrado | E4: P.U. (S/) | F4: Parcial (S/)
A5: 01 | B5: MOVIMIENTO DE TIERRAS (OE.2.1)
A6: 01.01 | B6: Excavación para zapatas | C6: m³ | D6: =Mov_Tierras!B5 -> 74.856 | F6: =IF(E6="","",D6*E6)
A7: 01.02 | B7: Excavación para vigas de cimentación | C7: m³ | D7: =Mov_Tierras!B6+Mov_Tierras!B7 -> 14.230125 | F7: =IF(E7="","",D7*E7)
A8: 01.03 | B8: Relleno compactado con material propio | C8: m³ | D8: =Mov_Tierras!B14 -> 50.126925 | F8: =IF(E8="","",D8*E8)
A9: 01.04 | B9: Eliminación de material excedente (esp. 25%) | C9: m³ | D9: =Mov_Tierras!B17 -> 48.699 | F9: =IF(E9="","",D9*E9)
A10: 02 | B10: OBRAS DE CONCRETO SIMPLE (OE.2.2)
A11: 02.01 | B11: Solado C:H 1:12, e = 0.10 m | C11: m² | D11: =Zapatas!J10 -> 46.785 | F11: =IF(E11="","",D11*E11)
A12: 03 | B12: OBRAS DE CONCRETO ARMADO (OE.2.3)
A13: 03.01 | B13: ZAPATAS
A14: 03.01.01 | B14: Concreto f'c = 210 kg/cm² en zapatas | C14: m³ | D14: =Zapatas!I10 -> 23.3925 | F14: =IF(E14="","",D14*E14)
A15: 03.01.02 | B15: Encofrado y desencofrado de zapatas (si se encofra) | C15: m² | D15: =Zapatas!L10 -> 53.4 | F15: =IF(E15="","",D15*E15)
A16: 03.01.03 | B16: Acero fy = 4200 kg/cm² en zapatas | C16: kg | D16: =Zapatas!R10 -> 822.8704 | F16: =IF(E16="","",D16*E16)
A17: 03.02 | B17: VIGAS DE CIMENTACIÓN
A18: 03.02.01 | B18: Concreto f'c = 210 kg/cm² en vigas de cimentación | C18: m³ | D18: =Vigas_Cimentacion!J31 -> 7.66245 | F18: =IF(E18="","",D18*E18)
A19: 03.02.02 | B19: Encofrado y desencofrado de vigas de cimentación | C19: m² | D19: =Vigas_Cimentacion!K31 -> 51.957 | F19: =IF(E19="","",D19*E19)
A20: 03.02.03 | B20: Acero fy = 4200 kg/cm² en vigas de cimentación | C20: kg | D20: =Vigas_Cimentacion!W31 -> 2097.2886 | F20: =IF(E20="","",D20*E20)
A21: 03.02.04 | B21: Tecnopor e = 0.10 m bajo vigas de equilibrio | C21: m² | D21: =Vigas_Cimentacion!L31 -> 7.3575 | F21: =IF(E21="","",D21*E21)
A22: 03.03 | B22: COLUMNAS
A23: 03.03.01 | B23: Concreto f'c = 210 kg/cm² en columnas | C23: m³ | D23: =Columnas!K16 -> 23.406 | F23: =IF(E23="","",D23*E23)
A24: 03.03.02 | B24: Encofrado y desencofrado de columnas | C24: m² | D24: =Columnas!K24 -> 210.97 | F24: =IF(E24="","",D24*E24)
A25: 03.03.03 | B25: Acero fy = 4200 kg/cm² en columnas | C25: kg | D25: =Columnas!B52 -> 6742.683 | F25: =IF(E25="","",D25*E25)
B26: COSTO DIRECTO (S/) | F26: =SUM(F5:F25) -> 0
A28: RESUMEN DE CONCRETO f'c 210 (m³)
B29: Zapatas | D29: =Zapatas!I10 -> 23.3925
B30: Vigas de cimentación | D30: =Vigas_Cimentacion!J31 -> 7.66245
B31: Columnas (incluye tramo bajo NTN) | D31: =Columnas!K16 -> 23.406
B32: TOTAL CONCRETO | D32: =SUM(D29:D31) -> 54.46095
A34: RESUMEN DE ACERO POR DIÁMETRO (kg)
B35: Elemento | C35: Ø3/8" | D35: Ø1/2" | E35: Ø5/8" | F35: Ø3/4" | G35: TOTAL
B36: Zapatas | C36: 0 | D36: 0 | E36: =Zapatas!R10 -> 822.8704 | F36: 0 | G36: =SUM(C36:F36) -> 822.8704
B37: Vigas de cimentación | C37: =Vigas_Cimentacion!V31 -> 468.6136 | D37: 0 | E37: =Vigas_Cimentacion!U31 -> 471.83904 | F37: =Vigas_Cimentacion!T31 -> 1156.836 | G37: =SUM(C37:F37) -> 2097.2886
B38: Columnas | C38: =Columnas!M43 -> 38.22 | D38: =Columnas!K43 -> 4164.9395 | E38: =Columnas!K34 -> 2224.3885 | F38: =Columnas!L34 -> 315.135 | G38: =SUM(C38:F38) -> 6742.683
B39: TOTAL | C39: =SUM(C36:C38) -> 506.8336 | D39: =SUM(D36:D38) -> 4164.9395 | E39: =SUM(E36:E38) -> 3519.0979 | F39: =SUM(F36:F38) -> 1471.971 | G39: =SUM(G36:G38) -> 9662.842
A41: Notas:
A42: • Vigas de cimentación con fondo a -1.50 (mismo nivel que zapatas); la parte embebida en la zapata se mide en la zapata.
A43: • Excavación a dimensiones netas. Si las zanjas de vigas se abren más anchas para encofrar, aumentan excavación y relleno.
A44: • Esponjamiento 25% supuesto; relleno hasta NTN ±0.00 (sin descontar falso piso).
...

Sheet Presupuesto
A1: PRESUPUESTO - Cimentación y columnas (excavación con máquina, concreto con mixer)
A2: Precios con IGV, Lima oct-2026, referenciales. Metrados reales de obra (zanjas al ancho del cucharón; zapatas vaciadas contra terreno).
A4: Ítem | B4: Descripción | C4: Und | D4: Metrado | E4: P.U. (S/) | F4: Parcial (S/) | G4: Cómo se obtuvo el metrado
A5: 01 | B5: MOVIMIENTO DE TIERRAS | F5: =SUM(F6:F9) -> 9615.7217
A6: 01.01 | B6: Movilización y desmovilización de retroexcavadora | C6: glb | D6: 1 | E6: =Insumos!$D$29 -> 600 | F6: =D6*E6 -> 600 | G6: Global
A7: 01.02 | B7: Excavación con retroexcavadora (zapatas y zanjas de vigas) | C7: m³ | D7: =(Mov_Tierras!B5+Insumos!$D$35*(Parametros!$B$15*(Vigas_Cimentacion!G28+Vigas_Cimentacion!G29)+Parametros!$B$16*Vigas_Cimentacion!G30)) -> 104.2995 | E7: =APU!$F$10 -> 18.430867 | F7: =D7*E7 -> 1922.3302 | G7: Zapatas neto + zanjas al ancho del cucharón (0.60)
A8: 01.03 | B8: Relleno compactado con material propio | C8: m³ | D8: =Mov_Tierras!B14+((Mov_Tierras!B5+Insumos!$D$35*(Parametros!$B$15*(Vigas_Cimentacion!G28+Vigas_Cimentacion!G29)+Parametros!$B$16*Vigas_Cimentacion!G30))-Mov_Tierras!B8) -> 65.3403 | E8: =APU!$F$20 -> 71.447354 | F8: =D8*E8 -> 4668.3916 | G8: Relleno neto + sobreexcavación de zanjas
A9: 01.04 | B9: Eliminación de material excedente (volquete 15 m³) | C9: viaje | D9: =ROUNDUP(Mov_Tierras!B17/Insumos!$D$31,0) -> 4 | E9: =APU!$F$27 -> 606.25 | F9: =D9*E9 -> 2425 | G9: Material suelto ÷ 15 m³
A10: 02 | B10: CONCRETO SIMPLE | F10: =SUM(F11:F11) -> 1494.0235
A11: 02.01 | B11: Solado C:H 1:12, e = 0.10 m | C11: m² | D11: =Zapatas!J10 -> 46.785 | E11: =APU!$F$40 -> 31.933813 | F11: =D11*E11 -> 1494.0235 | G11: Área de zapatas
A12: 03 | B12: CONCRETO ARMADO - CIMENTACIÓN | F12: =SUM(F13:F16) -> 34205.225
A13: 03.01 | B13: Concreto premezclado f'c 210 en zapatas + vigas de cimentación | C13: m³ | D13: =(Zapatas!I10+Vigas_Cimentacion!J31) -> 31.05495 | E13: =APU!$F$53 -> 479.19485 | F13: =D13*E13 -> 14881.372 | G13: Un vaciado monolítico
A14: 03.02 | B14: Encofrado y desencofrado de vigas de cimentación | C14: m² | D14: =Vigas_Cimentacion!K31 -> 51.957 | E14: =APU!$F$88 -> 43.525666 | F14: =D14*E14 -> 2261.4631 | G14: Zapatas sin encofrado (contra terreno)
A15: 03.03 | B15: Acero fy 4200 en zapatas y vigas de cimentación | C15: kg | D15: =Zapatas!R10+Vigas_Cimentacion!W31 -> 2920.159 | E15: =APU!$F$98 -> 5.7564373 | F15: =D15*E15 -> 16809.712
A16: 03.04 | B16: Tecnopor e = 0.10 m bajo vigas de equilibrio | C16: m² | D16: =Vigas_Cimentacion!L31 -> 7.3575 | E16: =APU!$F$116 -> 34.3428 | F16: =D16*E16 -> 252.67715
A17: 04 | B17: CONCRETO ARMADO - COLUMNAS | F17: =SUM(F18:F20) -> 66736.168
A18: 04.01 | B18: Concreto premezclado f'c 210 en columnas | C18: m³ | D18: =Columnas!K16 -> 23.406 | E18: =APU!$F$66 -> 609.52494 | F18: =D18*E18 -> 14266.541 | G18: 3 vaciados (piso 1 con tramo bajo NTN, piso 2, piso 3)
A19: 04.02 | B19: Encofrado y desencofrado de columnas | C19: m² | D19: =Columnas!K24 -> 210.97 | E19: =APU!$F$77 -> 51.014111 | F19: =D19*E19 -> 10762.447
A20: 04.03 | B20: Acero fy 4200 en columnas | C20: kg | D20: =Columnas!B52 -> 6742.683 | E20: =APU!$F$108 -> 6.1855467 | F20: =D20*E20 -> 41707.18
B21: COSTO DIRECTO | F21: =F5+F10+F12+F17 -> 112051.14
B22: Gastos generales | E22: =Insumos!$D$36 -> 0 | F22: =F21*E22 -> 0
B23: Utilidad | E23: =Insumos!$D$37 -> 0 | F23: =F21*E23 -> 0
B24: COSTO TOTAL (IGV incluido en insumos) | F24: =SUM(F21:F23) -> 112051.14
A26: INDICADORES
B27: Costo total ÷ m³ de concreto (indicador global) | F27: =F24/(D13+D18) -> 2057.4584 | G27: S/ por m³
B28: Concreto premezclado a pedir (con desperdicio) | F28: =(D13+D18)*(1+Insumos!$D$16) -> 56.094778 | G28: m³
B29: Viajes de mixer de 8 m³ (aprox.) | F29: =ROUNDUP(D13*(1+Insumos!$D$16)/8,0)+ROUNDUP((Columnas!G16+Columnas!H16)*(1+Insumos!$D$16)/8,0)+ROUNDUP(Columnas!I16*(1+Insumos!$D$16)/8,0)+ROUNDUP(Columnas!J16*(1+Insumos!$D$16)/8,0) -> 8 | G29: viajes
B30: Horas de retroexcavadora (excavación + carguío) | F30: =D7/Insumos!$D$28+D9*Insumos!$D$31/(2*Insumos!$D$28) -> 11.191625 | G30: h
B31: Acero total a comprar (con desperdicio) | F31: =(D15+D20)*(1+Insumos!$D$18) -> 10145.984 | G31: kg
A33: Notas:
A34: • Precios referenciales de mercado (Lima, oct-2026) con IGV. Reemplazar en la hoja Insumos por cotizaciones reales; todo se recalcula.
A35: • Concreto: el rango publicado en Lima va de S/ 260 a S/ 415/m³ según planta y zona; se usó S/ 380. Bomba S/ 40/m³ con mínimo 20 m³ por vaciado.
A36: • Zapatas vaciadas contra terreno (sin encofrado). Zanjas de VE/VC excavadas con cucharón de 0.60 m y encofradas.
A37: • No incluye: calzaduras, agua/luz de obra, ensayos de probetas, supervisión, vigas aéreas ni losas.
A38: • Columnas en 3 vaciados independientes: si se vacían junto con cada techo, la bomba se comparte y el costo baja.

Sheet Parametros
A1: PARÁMETROS GENERALES
A2: Celdas en AZUL = datos de entrada editables. Todo el libro se recalcula a partir de estas celdas y de las tablas de cada hoja.
A4: Parámetro | B4: Valor | C4: Und | D4: Fuente / nota
A5: Peso acero Ø3/8" | B5: 0.56 | C5: kg/m | D5: Peso nominal ASTM A615
A6: Peso acero Ø1/2" | B6: 0.994 | C6: kg/m | D6: Peso nominal ASTM A615
A7: Peso acero Ø5/8" | B7: 1.552 | C7: kg/m | D7: Peso nominal ASTM A615
A8: Peso acero Ø3/4" | B8: 2.235 | C8: kg/m | D8: Peso nominal ASTM A615
A9: Esponjamiento para eliminación | B9: 0.25 | D9: Supuesto (suelo gravoso/arenoso). Ajustar con EMS
A10: Nivel fondo de zapata (Df) | B10: -1.5 | C10: m | D10: E-01, nota 3
A11: Altura de zapata | B11: 0.5 | C11: m | D11: E-01, cuadro de zapatas
A12: Espesor de solado C:H 1:12 | B12: 0.1 | C12: m | D12: E-01, nota 2
A13: Espesor de tecnopor bajo VE | B13: 0.1 | C13: m | D13: E-01 nota 7 / E-02 nota 2
A14: Profundidad excavación zapatas | B14: =-Parametros!$B$10+Parametros!$B$12 -> 1.6 | C14: m | D14: Df + solado
A15: Profundidad excavación VE | B15: =-Parametros!$B$10+Parametros!$B$13 -> 1.6 | C15: m | D15: Fondo VE = fondo zapata (decisión de obra) + tecnopor
A16: Profundidad excavación VC | B16: =-Parametros!$B$10 -> 1.5 | C16: m | D16: Fondo VC -1.50 sobre terreno compactado
A17: Cara superior de zapata | B17: -1 | C17: m | D17: E-01 / E-04
A18: Nivel techo 1 | B18: 2.8 | C18: m | D18: E-04 elevación
A19: Nivel techo 2 | B19: 5.6 | C19: m | D19: E-04 elevación
A20: Nivel azotea | B20: 8.4 | C20: m | D20: E-04 elevación
A21: Peralte de vigas aéreas en columnas | B21: 0.5 | C21: m | D21: E-04: fondo de viga 0.50 bajo cada techo
A22: Recubrimiento columna al estribo | B22: 0.04 | C22: m | D22: E-04 nota 2
A23: Gancho 135° estribo Ø1/2" (c/u) | B23: 0.1 | C23: m | D23: 6db ≥ 7.5 cm + doblez. Supuesto
A24: Gancho estribo montaje Ø3/8" (c/u) | B24: 0.075 | C24: m | D24: Supuesto
A25: Nivel inferior barra de columna | B25: -1.39 | C25: m | D25: E-04: Ldc disponible 0.39 bajo cara de zapata
A26: Nivel superior barra de columna | B26: 8.35 | C26: m | D26: Azotea - 0.05. Supuesto
A27: Gancho 90° barras columna (pata) | B27: 0.2 | C27: m | D27: E-04 notas 9 y 10
A28: Empalme 1 Ø5/8" (piso 1) | B28: 0.95 | C28: m | D28: E-04 nota 8
... A33: Espaciamiento resto | B33: 0.09 | C33: m | D33: E-04

Sheet Zapatas
A1: ZAPATAS - Concreto, solado, encofrado, acero y excavación
A2: Fuente: lámina E-01. B = dimensión en X, L = dimensión en Y. Acero: parrilla Ø5/8" @0.20 a.s. (barras incluyen ganchos 0.20).
A4: Tipo | B4: Columnas | C4: Cant. | D4: B (m) | E4: L (m) | F4: h (m) | G4: Área c/u (m²) | H4: Concreto c/u (m³) | I4: CONCRETO (m³) | J4: SOLADO (m²) | K4: Encofrado c/u (m²) | L4: ENCOFRADO (m²) | M4: N° barras X | N4: Long. X (m) | O4: N° barras Y | P4: Long. Y (m) | Q4: Acero c/u (kg) | R4: ACERO Ø5/8" (kg) | S4: EXCAVACIÓN (m³)
A5: Z-1 | B5: B2 | C5: 1 | D5: 2.2 | E5: 2.2 | F5: =Parametros!$B$11 -> 0.5 | G5: =D5*E5 -> 4.84 | H5: =G5*F5 -> 2.42 | I5: =H5*C5 -> 2.42 | J5: =G5*C5 -> 4.84 | K5: =2*(D5+E5)*F5 -> 4.4 | L5: =K5*C5 -> 4.4 | M5: 11 | N5: 2.45 | O5: 11 | P5: 2.45 | Q5: =(M5*N5+O5*P5)*Parametros!$B$7 -> 83.6528 | R5: =Q5*C5 -> 83.6528 | S5: =G5*Parametros!$B$14*C5 -> 7.744
A6: Z-2 | B6: B3, B4 | C6: 2 | D6: 1.95 | E6: 1.95 | F6: =Parametros!$B$11 -> 0.5 | G6: =D6*E6 -> 3.8025 | H6: =G6*F6 -> 1.90125 | I6: =H6*C6 -> 3.8025 | J6: =G6*C6 -> 7.605 | K6: =2*(D6+E6)*F6 -> 3.9 | L6: =K6*C6 -> 7.8 | M6: 10 | N6: 2.2 | O6: 10 | P6: 2.2 | Q6: =(M6*N6+O6*P6)*Parametros!$B$7 -> 68.288 | R6: =Q6*C6 -> 136.576 | S6: =G6*Parametros!$B$14*C6 -> 12.168
A7: Z-3 | B7: A2, C2 | C7: 2 | D7: 1.4 | E7: 2.2 | F7: =Parametros!$B$11 -> 0.5 | G7: =D7*E7 -> 3.08 | H7: =G7*F7 -> 1.54 | I7: =H7*C7 -> 3.08 | J7: =G7*C7 -> 6.16 | K7: =2*(D7+E7)*F7 -> 3.6 | L7: =K7*C7 -> 7.2 | M7: 11 | N7: 1.65 | O7: 7 | P7: 2.45 | Q7: =(M7*N7+O7*P7)*Parametros!$B$7 -> 54.7856 | R7: =Q7*C7 -> 109.5712 | S7: =G7*Parametros!$B$14*C7 -> 9.856
A8: Z-4 | B8: A3, A4, C3, C4, B1*, B5* | C8: 6 | D8: 1.4 | E8: 2.1 | F8: =Parametros!$B$11 -> 0.5 | G8: =D8*E8 -> 2.94 | H8: =G8*F8 -> 1.47 | I8: =H8*C8 -> 8.82 | J8: =G8*C8 -> 17.64 | K8: =2*(D8+E8)*F8 -> 3.5 | L8: =K8*C8 -> 21 | M8: 10 | N8: 1.65 | O8: 7 | P8: 2.35 | Q8: =(M8*N8+O8*P8)*Parametros!$B$7 -> 51.1384 | R8: =Q8*C8 -> 306.8304 | S8: =G8*Parametros!$B$14*C8 -> 28.224
A9: Z-5 | B9: A1, A5, C1, C5 | C9: 4 | D9: 1.55 | E9: 1.7 | F9: =Parametros!$B$11 -> 0.5 | G9: =D9*E9 -> 2.635 | H9: =G9*F9 -> 1.3175 | I9: =H9*C9 -> 5.27 | J9: =G9*C9 -> 10.54 | K9: =2*(D9+E9)*F9 -> 3.25 | L9: =K9*C9 -> 13 | M9: 8 | N9: 1.8 | O9: 8 | P9: 1.95 | Q9: =(M9*N9+O9*P9)*Parametros!$B$7 -> 46.56 | R9: =Q9*C9 -> 186.24 | S9: =G9*Parametros!$B$14*C9 -> 16.864
A10: TOTAL | C10: =SUM(C5:C9) -> 15 | I10: =SUM(I5:I9) -> 23.3925 | J10: =SUM(J5:J9) -> 46.785 | L10: =SUM(L5:L9) -> 53.4 | R10: =SUM(R5:R9) -> 822.8704 | S10: =SUM(S5:S9) -> 74.856
A12: * En B1 y B5 la Z-4 va girada 90° (2.10 en X, 1.40 en Y); el volumen no cambia.
A13: Encofrado = perímetro × h. Si la zapata se vacía contra el terreno (excavación al ras), esta partida no se ejecuta.
A14: Excavación = área × profundidad (fondo de zapata + solado), desde NTN ±0.00.

Sheet Vigas_Cimentacion
A1: VIGAS DE CIMENTACIÓN - Concreto, encofrado, tecnopor, acero y excavación
A2: Fuente: E-02 (luces libres, acero, estribos) y E-01 (distancia libre entre zapatas). Fondo de viga al mismo nivel que la zapata (-1.50).
A4: Viga | B4: Tipo | C4: Ubicación | D4: b (m) | E4: h (m) | F4: L libre entre columnas (m) | G4: L entre zapatas (m) | H4: L sobre zapatas (m) | I4: h sobre zapata (m) | J4: CONCRETO (m³) | K4: ENCOFRADO (m²) | L4: TECNOPOR (m²) | M4: Prof. excav. (m) | N4: EXCAVACIÓN (m³) | O4: L barra (m) | P4: N° Ø3/4" | Q4: N° Ø5/8" | R4: N° estribos | S4: L estribo Ø3/8" (m) | T4: Ø3/4" (kg) | U4: Ø5/8" (kg) | V4: Ø3/8" (kg) | W4: ACERO TOTAL (kg)
A5: VE-1a | B5: VE-1 | C5: Eje 2: A2-B2 | D5: 0.3 | E5: 0.7 | F5: 3.55 | G5: 1.64 | H5: =F5-G5 -> 1.91 | I5: =MAX(0,E5-Parametros!$B$11) -> 0.2 | J5: =D5*E5*G5+D5*I5*H5 -> 0.459 | K5: =2*E5*G5+2*I5*H5 -> 3.06 | L5: =IF(LEFT(B5,2)="VE",D5*G5,0) -> 0.492 | M5: =IF(LEFT(B5,2)="VE",Parametros!$B$15,Parametros!$B$16) -> 1.6 | N5: =D5*M5*G5 -> 0.7872 | O5: 5.05 | P5: 8 | Q5: 2 | R5: 24 | S5: 1.93 | T5: =P5*O5*Parametros!$B$8 -> 90.294 | U5: =Q5*O5*Parametros!$B$7 -> 15.6752 | V5: =R5*S5*Parametros!$B$5 -> 25.9392 | W5: =SUM(T5:V5) -> 131.9084
A6: VE-1b | B6: VE-1 | C6: Eje 2: B2-C2 | D6: 0.3 | E6: 0.7 | F6: 3.15 | G6: 1.26 | H6: =F6-G6 -> 1.89 | I6: =MAX(0,E6-Parametros!$B$11) -> 0.2 | J6: =D6*E6*G6+D6*I6*H6 -> 0.378 | K6: =2*E6*G6+2*I6*H6 -> 2.52 | L6: =IF(LEFT(B6,2)="VE",D6*G6,0) -> 0.378 | M6: =IF(LEFT(B6,2)="VE",Parametros!$B$15,Parametros!$B$16) -> 1.6 | N6: =D6*M6*G6 -> 0.6048 | O6: 4.65 | P6: 8 | Q6: 2 | R6: 22 | S6: 1.93 | T6: =P6*O6*Parametros!$B$8 -> 83.142 | U6: =Q6*O6*Parametros!$B$7 -> 14.4336 | V6: =R6*S6*Parametros!$B$5 -> 23.7776 | W6: =SUM(T6:V6) -> 121.3532
A7: VE-1c | B7: VE-1 | C7: Eje B: B1-B2 | D7: 0.3 | E7: 0.7 | F7: 4.28 | G7: 2.25 | H7: =F7-G7 -> 2.03 | I7: =MAX(0,E7-Parametros!$B$11) -> 0.2 | J7: =D7*E7*G7+D7*I7*H7 -> 0.5943 | K7: =2*E7*G7+2*I7*H7 -> 3.962 | L7: =IF(LEFT(B7,2)="VE",D7*G7,0) -> 0.675 | M7: =IF(LEFT(B7,2)="VE",Parametros!$B$15,Parametros!$B$16) -> 1.6 | N7: =D7*M7*G7 -> 1.08 | O7: 5.78 | P7: 8 | Q7: 2 | R7: 29 | S7: 1.93 | T7: =P7*O7*Parametros!$B$8 -> 103.3464 | U7: =Q7*O7*Parametros!$B$7 -> 17.94112 | V7: =R7*S7*Parametros!$B$5 -> 31.3432 | W7: =SUM(T7:V7) -> 152.63072
A8: VE-1d | B8: VE-1 | C8: Eje B: B4-B5 | D8: 0.3 | E8: 0.7 | F8: 3.41 | G8: 1.515 | H8: =F8-G8 -> 1.895 | I8: =MAX(0,E8-Parametros!$B$11) -> 0.2 | J8: =D8*E8*G8+D8*I8*H8 -> 0.43185 | K8: =2*E8*G8+2*I8*H8 -> 2.879 | L8: =IF(LEFT(B8,2)="VE",D8*G8,0) -> 0.4545 | M8: =IF(LEFT(B8,2)="VE",Parametros!$B$15,Parametros!$B$16) -> 1.6 | N8: =D8*M8*G8 -> 0.7272 | O8: 4.91 | P8: 8 | Q8: 2 | R8: 24 | S8: 1.93 | T8: =P8*O8*Parametros!$B$8 -> 87.7908 | U8: =Q8*O8*Parametros!$B$7 -> 15.24064 | V8: =R8*S8*Parametros!$B$5 -> 25.9392 | W8: =SUM(T8:V8) -> 128.97064
A9: VE-2a | B9: VE-2 | C9: Eje 1: A1-B1 | D9: 0.3 | E9: 0.7 | F9: 3.55 | G9: 1.54 | H9: =F9-G9 -> 2.01 | I9: =MAX(0,E9-Parametros!$B$11) -> 0.2 | J9: =D9*E9*G9+D9*I9*H9 -> 0.444 | K9: =2*E9*G9+2*I9*H9 -> 2.96 | L9: =IF(LEFT(B9,2)="VE",D9*G9,0) -> 0.462 | M9: =IF(LEFT(B9,2)="VE",Parametros!$B$15,Parametros!$B$16) -> 1.6 | N9: =D9*M9*G9 -> 0.7392 | O9: 5.05 | P9: 6 | Q9: 2 | R9: 24 | S9: 1.93 | T9: =P9*O9*Parametros!$B$8 -> 67.7205 | U9: =Q9*O9*Parametros!$B$7 -> 15.6752 | V9: =R9*S9*Parametros!$B$5 -> 25.9392 | W9: =SUM(T9:V9) -> 109.3349
A10: VE-2b | B10: VE-2 | C10: Eje 1: B1-C1 | D10: 0.3 | E10: 0.7 | F10: 3.15 | G10: 1.15 | H10: =F10-G10 -> 2 | I10: =MAX(0,E10-Parametros!$B$11) -> 0.2 | J10: =D10*E10*G10+D10*I10*H10 -> 0.3615 | K10: =2*E10*G10+2*I10*H10 -> 2.41 | L10: =IF(LEFT(B10,2)="VE",D10*G10,0) -> 0.345 | M10: =IF(LEFT(B10,2)="VE",Parametros!$B$15,Parametros!$B$16) -> 1.6 | N10: =D10*M10*G10 -> 0.552 | O10: 4.65 | P10: 6 | Q10: 2 | R10: 22 | S10: 1.93 | T10: =P10*O10*Parametros!$B$8 -> 62.3565 | U10: =Q10*O10*Parametros!$B$7 -> 14.4336 | V10: =R10*S10*Parametros!$B$5 -> 23.7776 | W10: =SUM(T10:V10) -> 100.5677
A11: VE-2c | B11: VE-2 | C11: Eje 3: A3-B3 | D11: 0.3 | E11: 0.7 | F11: 3.55 | G11: 1.765 | H11: =F11-G11 -> 1.785 | I11: =MAX(0,E11-Parametros!$B$11) -> 0.2 | J11: =D11*E11*G11+D11*I11*H11 -> 0.47775 | K11: =2*E11*G11+2*I11*H11 -> 3.185 | L11: =IF(LEFT(B11,2)="VE",D11*G11,0) -> 0.5295 | M11: =IF(LEFT(B11,2)="VE",Parametros!$B$15,Parametros!$B$16) -> 1.6 | N11: =D11*M11*G11 -> 0.8472 | O11: 5.05 | P11: 6 | Q11: 2 | R11: 24 | S11: 1.93 | T11: =P11*O11*Parametros!$B$8 -> 67.7205 | U11: =Q11*O11*Parametros!$B$7 -> 15.6752 | V11: =R11*S11*Parametros!$B$5 -> 25.9392 | W11: =SUM(T11:V11) -> 109.3349
A12: VE-2d | B12: VE-2 | C12: Eje 3: B3-C3 | D12: 0.3 | E12: 0.7 | F12: 3.15 | G12: 1.385 | H12: =F12-G12 -> 1.765 | I12: =MAX(0,E12-Parametros!$B$11) -> 0.2 | J12: =D12*E12*G12+D12*I12*H12 -> 0.39675 | K12: =2*E12*G12+2*I12*H12 -> 2.645 | L12: =IF(LEFT(B12,2)="VE",D12*G12,0) -> 0.4155 | M12: =IF(LEFT(B12,2)="VE",Parametros!$B$15,Parametros!$B$16) -> 1.6 | N12: =D12*M12*G12 -> 0.6648 | O12: 4.65 | P12: 6 | Q12: 2 | R12: 22 | S12: 1.93 | T12: =P12*O12*Parametros!$B$8 -> 62.3565 | U12: =Q12*O12*Parametros!$B$7 -> 14.4336 | V12: =R12*S12*Parametros!$B$5 -> 23.7776 | W12: =SUM(T12:V12) -> 100.5677
A13: VE-2e | B13: VE-2 | C13: Eje 4: A4-B4 | D13: 0.3 | E13: 0.7 | F13: 3.55 | G13: 1.765 | H13: =F13-G13 -> 1.785 | I13: =MAX(0,E13-Parametros!$B$11) -> 0.2 | J13: =D13*E13*G13+D13*I13*H13 -> 0.47775 | K13: =2*E13*G13+2*I13*H13 -> 3.185 | L13: =IF(LEFT(B13,2)="VE",D13*G13,0) -> 0.5295 | M13: =IF(LEFT(B13,2)="VE",Parametros!$B$15,Parametros!$B$16) -> 1.6 | N13: =D13*M13*G13 -> 0.8472 | O13: 5.05 | P13: 6 | Q13: 2 | R13: 24 | S13: 1.93 | T13: =P13*O13*Parametros!$B$8 -> 67.7205 | U13: =Q13*O13*Parametros!$B$7 -> 15.6752 | V13: =R13*S13*Parametros!$B$5 -> 25.9392 | W13: =SUM(T13:V13) -> 109.3349
A14: VE-2f | B14: VE-2 | C14: Eje 4: B4-C4 | D14: 0.3 | E14: 0.7 | F14: 3.15 | G14: 1.385 | H14: =F14-G14 -> 1.765 | I14: =MAX(0,E14-Parametros!$B$11) -> 0.2 | J14: =D14*E14*G14+D14*I14*H14 -> 0.39675 | K14: =2*E14*G14+2*I14*H14 -> 2.645 | L14: =IF(LEFT(B14,2)="VE",D14*G14,0) -> 0.4155 | M14: =IF(LEFT(B14,2)="VE",Parametros!$B$15,Parametros!$B$16) -> 1.6 | N14: =D14*M14*G14 -> 0.6648 | O14: 4.65 | P14: 6 | Q14: 2 | R14: 22 | S14: 1.93 | T14: =P14*O14*Parametros!$B$8 -> 62.3565 | U14: =Q14*O14*Parametros!$B$7 -> 14.4336 | V14: =R14*S14*Parametros!$B$5 -> 23.7776 | W14: =SUM(T14:V14) -> 100.5677
A15: VE-2g | B15: VE-2 | C15: Eje 5: A5-B5 | D15: 0.3 | E15: 0.7 | F15: 3.55 | G15: 1.54 | H15: =F15-G15 -> 2.01 | I15: =MAX(0,E15-Parametros!$B$11) -> 0.2 | J15: =D15*E15*G15+D15*I15*H15 -> 0.444 | K15: =2*E15*G15+2*I15*H15 -> 2.96 | L15: =IF(LEFT(B15,2)="VE",D15*G15,0) -> 0.462 | M15: =IF(LEFT(B15,2)="VE",Parametros!$B$15,Parametros!$B$16) -> 1.6 | N15: =D15*M15*G15 -> 0.7392 | O15: 5.05 | P15: 6 | Q15: 2 | R15: 24 | S15: 1.93 | T15: =P15*O15*Parametros!$B$8 -> 67.7205 | U15: =Q15*O15*Parametros!$B$7 -> 15.6752 | V15: =R15*S15*Parametros!$B$5 -> 25.9392 | W15: =SUM(T15:V15) -> 109.3349
A16: VE-2h | B16: VE-2 | C16: Eje 5: B5-C5 | D16: 0.3 | E16: 0.7 | F16: 3.15 | G16: 1.15 | H16: =F16-G16 -> 2 | I16: =MAX(0,E16-Parametros!$B$11) -> 0.2 | J16: =D16*E16*G16+D16*I16*H16 -> 0.3615 | K16: =2*E16*G16+2*I16*H16 -> 2.41 | L16: =IF(LEFT(B16,2)="VE",D16*G16,0) -> 0.345 | M16: =IF(LEFT(B16,2)="VE",Parametros!$B$15,Parametros!$B$16) -> 1.6 | N16: =D16*M16*G16 -> 0.552 | O16: 4.65 | P16: 6 | Q16: 2 | R16: 22 | S16: 1.93 | T16: =P16*O16*Parametros!$B$8 -> 62.3565 | U16: =Q16*O16*Parametros!$B$7 -> 14.4336 | V16: =R16*S16*Parametros!$B$5 -> 23.7776 | W16: =SUM(T16:V16) -> 100.5677
... A26: VCf | B26: VC | C26: Eje B: B3-B4 | D26: 0.25 | E26: 0.4 | F26: 2.83 | G26: 1.23 | H26: =F26-G26 -> 1.6 | I26: =MAX(0,E26-Parametros!$B$11) -> 0 | J26: =D26*E26*G26+D26*I26*H26 -> 0.123 | K26: =2*E26*G26+2*I26*H26 -> 0.984 | L26: =IF(LEFT(B26,2)="VE",D26*G26,0) -> 0 | M26: =IF(LEFT(B26,2)="VE",Parametros!$B$15,Parametros!$B$16) -> 1.5 | N26: =D26*M26*G26 -> 0.46125 | O26: 4.13 | P26: 0 | Q26: 6 | R26: 15 | S26: 1.18 | T26: =P26*O26*Parametros!$B$8 -> 0 | U26: =Q26*O26*Parametros!$B$7 -> 38.45856 | V26: =R26*S26*Parametros!$B$5 -> 9.912 | W26: =SUM(T26:V26) -> 48.37056
A28: Subtotal | B28: VE-1 | C28: =COUNTIF($B$5:$B$26,B28)&" und" -> 4 und | F28: =SUMIF($B$5:$B$26,$B28,F$5:F$26) -> 14.39 | G28: =SUMIF($B$5:$B$26,$B28,G$5:G$26) -> 6.665 | H28: =SUMIF($B$5:$B$26,$B28,H$5:H$26) -> 7.725 | J28: =SUMIF($B$5:$B$26,$B28,J$5:J$26) -> 1.86315 | K28: =SUMIF($B$5:$B$26,$B28,K$5:K$26) -> 12.421 | L28: =SUMIF($B$5:$B$26,$B28,L$5:L$26) -> 1.9995 | N28: =SUMIF($B$5:$B$26,$B28,N$5:N$26) -> 3.1992 | T28: =SUMIF($B$5:$B$26,$B28,T$5:T$26) -> 364.5732 | U28: =SUMIF($B$5:$B$26,$B28,U$5:U$26) -> 63.29056 | V28: =SUMIF($B$5:$B$26,$B28,V$5:V$26) -> 106.9992 | W28: =SUMIF($B$5:$B$26,$B28,W$5:W$26) -> 534.86296
A29: Subtotal | B29: VE-2 | C29: =COUNTIF($B$5:$B$26,B29)&" und" -> 12 und | F29: =SUMIF($B$5:$B$26,$B29,F$5:F$26) -> 41.08 | G29: =SUMIF($B$5:$B$26,$B29,G$5:G$26) -> 17.86 | H29: =SUMIF($B$5:$B$26,$B29,H$5:H$26) -> 23.22 | J29: =SUMIF($B$5:$B$26,$B29,J$5:J$26) -> 5.1438 | K29: =SUMIF($B$5:$B$26,$B29,K$5:K$26) -> 34.292 | L29: =SUMIF($B$5:$B$26,$B29,L$5:L$26) -> 5.358 | N29: =SUMIF($B$5:$B$26,$B29,N$5:N$26) -> 8.5728 | T29: =SUMIF($B$5:$B$26,$B29,T$5:T$26) -> 792.2628 | U29: =SUMIF($B$5:$B$26,$B29,U$5:U$26) -> 183.38432 | V29: =SUMIF($B$5:$B$26,$B29,V$5:V$26) -> 304.7856 | W29: =SUMIF($B$5:$B$26,$B29,W$5:W$26) -> 1280.4327
A30: Subtotal | B30: VC | C30: =COUNTIF($B$5:$B$26,B30)&" und" -> 6 und | F30: =SUMIF($B$5:$B$26,$B30,F$5:F$26) -> 16.38 | G30: =SUMIF($B$5:$B$26,$B30,G$5:G$26) -> 6.555 | H30: =SUMIF($B$5:$B$26,$B30,H$5:H$26) -> 9.825 | J30: =SUMIF($B$5:$B$26,$B30,J$5:J$26) -> 0.6555 | K30: =SUMIF($B$5:$B$26,$B30,K$5:K$26) -> 5.244 | L30: =SUMIF($B$5:$B$26,$B30,L$5:L$26) -> 0 | N30: =SUMIF($B$5:$B$26,$B30,N$5:N$26) -> 2.458125 | T30: =SUMIF($B$5:$B$26,$B30,T$5:T$26) -> 0 | U30: =SUMIF($B$5:$B$26,$B30,U$5:U$26) -> 225.16416 | V30: =SUMIF($B$5:$B$26,$B30,V$5:V$26) -> 56.8288 | W30: =SUMIF($B$5:$B$26,$B30,W$5:W$26) -> 281.99296
A31: TOTAL | F31: =SUM(F28:F30) -> 71.85 | G31: =SUM(G28:G30) -> 31.08 | H31: =SUM(H28:H30) -> 40.77 | J31: =SUM(J28:J30) -> 7.66245 | K31: =SUM(K28:K30) -> 51.957 | L31: =SUM(L28:L30) -> 7.3575 | N31: =SUM(N28:N30) -> 14.230125 | T31: =SUM(T28:T30) -> 1156.836 | U31: =SUM(U28:U30) -> 471.83904 | V31: =SUM(V28:V30) -> 468.6136 | W31: =SUM(W28:W30) -> 2097.2886
A33: L entre zapatas: distancia libre entre caras de zapata (cotas de E-01, verificada con E-04).
A34: L sobre zapatas = L libre entre columnas - L entre zapatas. Sobre la zapata solo se mide la parte de viga que sobresale de su cara superior (-1.00): h - 0.50.
A35: Concreto = b×h×L entre zapatas + b×(h sobre zapata)×L sobre zapatas (el volumen embebido ya está en la zapata, Norma de Metrados).
A36: Encofrado = 2 caras laterales. Si la zanja se excava al ancho de la viga y se vacía contra terreno, no se ejecuta.
A37: Acero según E-02: VE-1 4Ø3/4"+1Ø5/8" sup. e inf.; VE-2 3Ø3/4"+1Ø5/8" sup. e inf.; VC 3Ø5/8" sup. e inf. L barra y N° estribos del Cuadro de Vigas.

Sheet Columnas
A1: COLUMNAS - Concreto, encofrado y acero (desde cara superior de zapata hasta azotea)
A2: Fuente: E-04. Sección b (X) × h (Y). Concreto: altura entre cara superior de zapata/techo y cara superior del techo siguiente (incluye nudos).
A4: Tipo | B4: Ubicación | C4: Cant. | D4: b X (m) | E4: h Y (m) | F4: Área (m²) | G4: Perímetro (m)
A5: C-1 | B5: A1, A5, C1, C5 | C5: 4 | D5: 0.3 | E5: 0.5 | F5: =D5*E5 -> 0.15 | G5: =2*(D5+E5) -> 1.6
A6: C-2 | B6: A2, A3, A4, C2, C3, C4 | C6: 6 | D6: 0.3 | E6: 0.5 | F6: =D6*E6 -> 0.15 | G6: =2*(D6+E6) -> 1.6
A7: C-3 | B7: B1, B5 | C7: 2 | D7: 0.6 | E7: 0.3 | F7: =D7*E7 -> 0.18 | G7: =2*(D7+E7) -> 1.8
A8: C-4 | B8: B2, B3, B4 | C8: 3 | D8: 0.6 | E8: 0.35 | F8: =D8*E8 -> 0.21 | G8: =2*(D8+E8) -> 1.9
A10: 1. CONCRETO f'c 210 (m³)
A11: Tipo | B11: Cant. | C11: h bajo NTN (m) | D11: h piso 1 (m) | E11: h piso 2 (m) | F11: h piso 3 (m) | G11: Vol. bajo NTN | H11: Vol. piso 1 | I11: Vol. piso 2 | J11: Vol. piso 3 | K11: CONCRETO TOTAL (m³)
A12: =A5 -> C-1 | B12: =C5 -> 4 | C12: =0-Parametros!$B$17 -> 1 | D12: =Parametros!$B$18-0 -> 2.8 | E12: =Parametros!$B$19-Parametros!$B$18 -> 2.8 | F12: =Parametros!$B$20-Parametros!$B$19 -> 2.8 | G12: =$F5*C12*$B12 -> 0.6 | H12: =$F5*D12*$B12 -> 1.68 | I12: =$F5*E12*$B12 -> 1.68 | J12: =$F5*F12*$B12 -> 1.68 | K12: =SUM(G12:J12) -> 5.64
A13: =A6 -> C-2 | B13: =C6 -> 6 | C13: =0-Parametros!$B$17 -> 1 | D13: =Parametros!$B$18-0 -> 2.8 | E13: =Parametros!$B$19-Parametros!$B$18 -> 2.8 | F13: =Parametros!$B$20-Parametros!$B$19 -> 2.8 | G13: =$F6*C13*$B13 -> 0.9 | H13: =$F6*D13*$B13 -> 2.52 | I13: =$F6*E13*$B13 -> 2.52 | J13: =$F6*F13*$B13 -> 2.52 | K13: =SUM(G13:J13) -> 8.46
A14: =A7 -> C-3 | B14: =C7 -> 2 | C14: =0-Parametros!$B$17 -> 1 | D14: =Parametros!$B$18-0 -> 2.8 | E14: =Parametros!$B$19-Parametros!$B$18 -> 2.8 | F14: =Parametros!$B$20-Parametros!$B$19 -> 2.8 | G14: =$F7*C14*$B14 -> 0.36 | H14: =$F7*D14*$B14 -> 1.008 | I14: =$F7*E14*$B14 -> 1.008 | J14: =$F7*F14*$B14 -> 1.008 | K14: =SUM(G14:J14) -> 3.384
A15: =A8 -> C-4 | B15: =C8 -> 3 | C15: =0-Parametros!$B$17 -> 1 | D15: =Parametros!$B$18-0 -> 2.8 | E15: =Parametros!$B$19-Parametros!$B$18 -> 2.8 | F15: =Parametros!$B$20-Parametros!$B$19 -> 2.8 | G15: =$F8*C15*$B15 -> 0.63 | H15: =$F8*D15*$B15 -> 1.764 | I15: =$F8*E15*$B15 -> 1.764 | J15: =$F8*F15*$B15 -> 1.764 | K15: =SUM(G15:J15) -> 5.922
A16: TOTAL | G16: =SUM(G12:G15) -> 2.49 | H16: =SUM(H12:H15) -> 6.972 | I16: =SUM(I12:I15) -> 6.972 | J16: =SUM(J12:J15) -> 6.972 | K16: =SUM(K12:K15) -> 23.406
A18: 2. ENCOFRADO Y DESENCOFRADO (m²)
A19: Tipo | B19: Cant. | C19: ln bajo NTN (m) | D19: ln piso 1 sobre NTN (m) | E19: ln piso 2 (m) | F19: ln piso 3 (m) | G19: Encof. fustes (m²) | H19: Caras ext. en nudo (m) | I19: N° nudos | J19: Encof. nudos (m²) | K19: ENCOFRADO TOTAL (m²)
A20: =A5 -> C-1 | B20: =C5 -> 4 | C20: =0-Parametros!$B$17 -> 1 | D20: =Parametros!$B$18-Parametros!$B$21 -> 2.3 | E20: =Parametros!$B$19-Parametros!$B$21-Parametros!$B$18 -> 2.3 | F20: =Parametros!$B$20-Parametros!$B$21-Parametros!$B$19 -> 2.3 | G20: =G5*SUM(C20:F20)*B20 -> 50.56 | H20: 0.8 | I20: 3 | J20: =H20*Parametros!$B$21*I20*B20 -> 4.8 | K20: =G20+J20 -> 55.36
A21: =A6 -> C-2 | B21: =C6 -> 6 | C21: =0-Parametros!$B$17 -> 1 | D21: =Parametros!$B$18-Parametros!$B$21 -> 2.3 | E21: =Parametros!$B$19-Parametros!$B$21-Parametros!$B$18 -> 2.3 | F21: =Parametros!$B$20-Parametros!$B$21-Parametros!$B$19 -> 2.3 | G21: =G6*SUM(C21:F21)*B21 -> 75.84 | H21: 0.5 | I21: 3 | J21: =H21*Parametros!$B$21*I21*B21 -> 4.5 | K21: =G21+J21 -> 80.34
A22: =A7 -> C-3 | B22: =C7 -> 2 | C22: =0-Parametros!$B$17 -> 1 | D22: =Parametros!$B$18-Parametros!$B$21 -> 2.3 | E22: =Parametros!$B$19-Parametros!$B$21-Parametros!$B$18 -> 2.3 | F22: =Parametros!$B$20-Parametros!$B$21-Parametros!$B$19 -> 2.3 | G22: =G7*SUM(C22:F22)*B22 -> 28.44 | H22: 0.6 | I22: 3 | J22: =H22*Parametros!$B$21*I22*B22 -> 1.8 | K22: =G22+J22 -> 30.24
A23: =A8 -> C-4 | B23: =C8 -> 3 | C23: =0-Parametros!$B$17 -> 1 | D23: =Parametros!$B$18-Parametros!$B$21 -> 2.3 | E23: =Parametros!$B$19-Parametros!$B$21-Parametros!$B$18 -> 2.3 | F23: =Parametros!$B$20-Parametros!$B$21-Parametros!$B$19 -> 2.3 | G23: =G8*SUM(C23:F23)*B23 -> 45.03 | H23: 0 | I23: 3 | J23: =H23*Parametros!$B$21*I23*B23 -> 0 | K23: =G23+J23 -> 45.03
A24: TOTAL | G24: =SUM(G20:G23) -> 199.87 | J24: =SUM(J20:J23) -> 11.1 | K24: =SUM(K20:K23) -> 210.97
A25: Fuste: perímetro × altura libre hasta fondo de viga (ln piso 1 = 3.30 desde -1.00; pisos 2 y 3 = 2.30). Nudos: solo caras exteriores sin viga que llegue (lindero / frente) × peralte 0.50.
A26: Caras ext.: C-1 esquina 0.50+0.30; C-2 lindero 0.50; C-3 frente 0.60; C-4 interior 0. Supuesto: vigas aéreas en todos los ejes (plano de vigas aéreas no proporcionado).
A28: 3. ACERO LONGITUDINAL (kg)
A29: Tipo | B29: Cant. | C29: N° Ø5/8" continuas | D29: L Ø5/8" continua (m) | E29: N° Ø5/8" hasta empalme 2 | F29: L Ø5/8" a empalme 2 (m) | G29: N° Ø3/4" piso 3 | H29: L Ø3/4" (m) | I29: Ø5/8" por col. (kg) | J29: Ø3/4" por col. (kg) | K29: Ø5/8" TOTAL (kg) | L29: Ø3/4" TOTAL (kg)
A30: =A5 -> C-1 | B30: =C5 -> 4 | C30: 8 | D30: =Parametros!$B$26-Parametros!$B$25+2*Parametros!$B$27+Parametros!$B$28 -> 11.09 | E30: 0 | F30: =((Parametros!$B$19+Parametros!$B$20-Parametros!$B$21)/2+Parametros!$B$29/2)-Parametros!$B$25+Parametros!$B$27+Parametros!$B$28 -> 9.84 | G30: 0 | H30: =Parametros!$B$26-((Parametros!$B$19+Parametros!$B$20-Parametros!$B$21)/2-Parametros!$B$29/2)+Parametros!$B$27 -> 2.35 | I30: =(C30*D30+E30*F30)*Parametros!$B$7 -> 137.69344 | J30: =G30*H30*Parametros!$B$8 -> 0 | K30: =I30*B30 -> 550.77376 | L30: =J30*B30 -> 0
A31: =A6 -> C-2 | B31: =C6 -> 6 | C31: 2 | D31: =Parametros!$B$26-Parametros!$B$25+2*Parametros!$B$27+Parametros!$B$28 -> 11.09 | E31: 6 | F31: =((Parametros!$B$19+Parametros!$B$20-Parametros!$B$21)/2+Parametros!$B$29/2)-Parametros!$B$25+Parametros!$B$27+Parametros!$B$28 -> 9.84 | G31: 6 | H31: =Parametros!$B$26-((Parametros!$B$19+Parametros!$B$20-Parametros!$B$21)/2-Parametros!$B$29/2)+Parametros!$B$27 -> 2.35 | I31: =(C31*D31+E31*F31)*Parametros!$B$7 -> 126.05344 | J31: =G31*H31*Parametros!$B$8 -> 31.5135 | K31: =I31*B31 -> 756.32064 | L31: =J31*B31 -> 189.081
A32: =A7 -> C-3 | B32: =C7 -> 2 | C32: 10 | D32: =Parametros!$B$26-Parametros!$B$25+2*Parametros!$B$27+Parametros!$B$28 -> 11.09 | E32: 0 | F32: =((Parametros!$B$19+Parametros!$B$20-Parametros!$B$21)/2+Parametros!$B$29/2)-Parametros!$B$25+Parametros!$B$27+Parametros!$B$28 -> 9.84 | G32: 0 | H32: =Parametros!$B$26-((Parametros!$B$19+Parametros!$B$20-Parametros!$B$21)/2-Parametros!$B$29/2)+Parametros!$B$27 -> 2.35 | I32: =(C32*D32+E32*F32)*Parametros!$B$7 -> 172.1168 | J32: =G32*H32*Parametros!$B$8 -> 0 | K32: =I32*B32 -> 344.2336 | L32: =J32*B32 -> 0
A33: =A8 -> C-4 | B33: =C8 -> 3 | C33: 4 | D33: =Parametros!$B$26-Parametros!$B$25+2*Parametros!$B$27+Parametros!$B$28 -> 11.09 | E33: 8 | F33: =((Parametros!$B$19+Parametros!$B$20-Parametros!$B$21)/2+Parametros!$B$29/2)-Parametros!$B$25+Parametros!$B$27+Parametros!$B$28 -> 9.84 | G33: 8 | H33: =Parametros!$B$26-((Parametros!$B$19+Parametros!$B$20-Parametros!$B$21)/2-Parametros!$B$29/2)+Parametros!$B$27 -> 2.35 | I33: =(C33*D33+E33*F33)*Parametros!$B$7 -> 191.02016 | J33: =G33*H33*Parametros!$B$8 -> 42.018 | K33: =I33*B33 -> 573.06048 | L33: =J33*B33 -> 126.054
A34: TOTAL | K34: =SUM(K30:K33) -> 2224.3885 | L34: =SUM(L30:L33) -> 315.135
A35: Barras desde -1.39 (gancho 0.20 sobre parrilla) hasta +8.35 (gancho 0.20). Empalme 1 Ø5/8" L=0.95 en piso 1. C-2/C-4: cambio a Ø3/4" en piso 3 con empalme 2 L=1.10 al centro de ln piso 3.
A37: 4. ESTRIBOS Ø1/2" Y MONTAJE Ø3/8" (kg)
A38: Tipo | B38: Cant. | C38: N° piso 1 | D38: N° piso 2 | E38: N° piso 3 | F38: N° nudos | G38: N° total por col. | H38: L estribo ext. (m) | I38: L pieza interior (m) | J38: Ø1/2" por col. (kg) | K38: Ø1/2" TOTAL (kg) | L38: L montaje Ø3/8" (m) | M38: Ø3/8" TOTAL (kg) (3 und/col)
A39: =A5 -> C-1 | B39: =C5 -> 4 | C39: =2*Parametros!$B$30+ROUNDUP(Parametros!$B$28/Parametros!$B$32,0)+ROUNDUP(((Parametros!$B$18-Parametros!$B$21-Parametros!$B$17)-2*Parametros!$B$31-Parametros!$B$28)/Parametros!$B$33,0) -> 43 | D39: =2*Parametros!$B$30+ROUNDUP(((Parametros!$B$19-Parametros!$B$21-Parametros!$B$18)-2*Parametros!$B$31)/Parametros!$B$33,0) -> 30 | E39: =2*Parametros!$B$30+ROUNDUP(((Parametros!$B$19-Parametros!$B$21-Parametros!$B$18)-2*Parametros!$B$31)/Parametros!$B$33,0) -> 30 | F39: =3*ROUNDUP(Parametros!$B$21/Parametros!$B$32,0) -> 21 | G39: =SUM(C39:F39) -> 124 | H39: =2*(D5+E5)-8*Parametros!$B$22+2*Parametros!$B$23 -> 1.48 | I39: =D5-2*Parametros!$B$22+2*Parametros!$B$23 -> 0.42 | J39: =G39*(H39+I39)*Parametros!$B$6 -> 234.1864 | K39: =J39*B39 -> 936.7456 | L39: =2*(D5+E5)-8*Parametros!$B$22+2*Parametros!$B$24 -> 1.43 | M39: =3*L39*Parametros!$B$5*B39 -> 9.6096
A40: =A6 -> C-2 | B40: =C6 -> 6 | C40: =2*Parametros!$B$30+ROUNDUP(Parametros!$B$28/Parametros!$B$32,0)+ROUNDUP(((Parametros!$B$18-Parametros!$B$21-Parametros!$B$17)-2*Parametros!$B$31-Parametros!$B$28)/Parametros!$B$33,0) -> 43 | D40: =2*Parametros!$B$30+ROUNDUP(((Parametros!$B$19-Parametros!$B$21-Parametros!$B$18)-2*Parametros!$B$31)/Parametros!$B$33,0) -> 30 | E40: =2*Parametros!$B$30+ROUNDUP(((Parametros!$B$19-Parametros!$B$21-Parametros!$B$18)-2*Parametros!$B$31)/Parametros!$B$32,0) -> 32 | F40: =3*ROUNDUP(Parametros!$B$21/Parametros!$B$32,0) -> 21 | G40: =SUM(C40:F40) -> 126 | H40: =2*(D6+E6)-8*Parametros!$B$22+2*Parametros!$B$23 -> 1.48 | I40: =D6-2*Parametros!$B$22+2*Parametros!$B$23 -> 0.42 | J40: =G40*(H40+I40)*Parametros!$B$6 -> 237.9636 | K40: =J40*B40 -> 1427.7816 | L40: =2*(D6+E6)-8*Parametros!$B$22+2*Parametros!$B$24 -> 1.43 | M40: =3*L40*Parametros!$B$5*B40 -> 14.4144
A41: =A7 -> C-3 | B41: =C7 -> 2 | C41: =2*Parametros!$B$30+ROUNDUP(Parametros!$B$28/Parametros!$B$32,0)+ROUNDUP(((Parametros!$B$18-Parametros!$B$21-Parametros!$B$17)-2*Parametros!$B$31-Parametros!$B$28)/Parametros!$B$33,0) -> 43 | D41: =2*Parametros!$B$30+ROUNDUP(((Parametros!$B$19-Parametros!$B$21-Parametros!$B$18)-2*Parametros!$B$31)/Parametros!$B$33,0) -> 30 | E41: =2*Parametros!$B$30+ROUNDUP(((Parametros!$B$19-Parametros!$B$21-Parametros!$B$18)-2*Parametros!$B$31)/Parametros!$B$33,0) -> 30 | F41: =3*ROUNDUP(Parametros!$B$21/Parametros!$B$32,0) -> 21 | G41: =SUM(C41:F41) -> 124 | H41: =2*(D7+E7)-8*Parametros!$B$22+2*Parametros!$B$23 -> 1.68 | I41: =2*(0.175+E7-2*Parametros!$B$22)+2*Parametros!$B$23 -> 0.99 | J41: =G41*(H41+I41)*Parametros!$B$6 -> 329.09352 | K41: =J41*B41 -> 658.18704 | L41: =2*(D7+E7)-8*Parametros!$B$22+2*Parametros!$B$24 -> 1.63 | M41: =3*L41*Parametros!$B$5*B41 -> 5.4768
A42: =A8 -> C-4 | B42: =C8 -> 3 | C42: =2*Parametros!$B$30+ROUNDUP(Parametros!$B$28/Parametros!$B$32,0)+ROUNDUP(((Parametros!$B$18-Parametros!$B$21-Parametros!$B$17)-2*Parametros!$B$31-Parametros!$B$28)/Parametros!$B$33,0) -> 43 | D42: =2*Parametros!$B$30+ROUNDUP(((Parametros!$B$19-Parametros!$B$21-Parametros!$B$18)-2*Parametros!$B$31)/Parametros!$B$33,0) -> 30 | E42: =2*Parametros!$B$30+ROUNDUP(((Parametros!$B$19-Parametros!$B$21-Parametros!$B$18)-2*Parametros!$B$31)/Parametros!$B$32,0) -> 32 | F42: =3*ROUNDUP(Parametros!$B$21/Parametros!$B$32,0) -> 21 | G42: =SUM(C42:F42) -> 126 | H42: =2*(D8+E8)-8*Parametros!$B$22+2*Parametros!$B$23 -> 1.78 | I42: =2*(0.26+E8-2*Parametros!$B$22)+2*Parametros!$B$23 -> 1.26 | J42: =G42*(H42+I42)*Parametros!$B$6 -> 380.74176 | K42: =J42*B42 -> 1142.2253 | L42: =2*(D8+E8)-8*Parametros!$B$22+2*Parametros!$B$24 -> 1.73 | M42: =3*L42*Parametros!$B$5*B42 -> 8.7192
A43: TOTAL | K43: =SUM(K39:K42) -> 4164.9395 | M43: =SUM(M39:M42) -> 38.22
A44: Cada ln: 1@0.05 + 8@0.075 en cada extremo, resto @0.09; empalmes y nudos @0.075 (E-04). Piso 3 de C-2/C-4: el empalme 2 (1.10) ocupa toda la zona central → @0.075.
A45: Pieza interior: C-1/C-2 gancho suplementario a lo largo del lado de 0.30; C-3 estribo interior ≈0.175×0.22; C-4 estribo interior ≈0.26×0.27 (medidos del dibujo de secciones E-04).
...

Sheet Mov_Tierras
A1: MOVIMIENTO DE TIERRAS - Excavación, relleno y eliminación
A2: Excavación medida a dimensiones netas de los elementos (Norma de Metrados). Relleno hasta NTN ±0.00.
A4: Concepto | B4: m³ | C4: Referencia
A5: Excavación zapatas | B5: =Zapatas!S10 -> 74.856 | C5: Zapatas: área × (Df + solado)
A6: Excavación vigas de equilibrio VE | B6: =SUMIF(Vigas_Cimentacion!B5:B26,"VE*",Vigas_Cimentacion!N5:N26) -> 11.772 | C6: b × (1.50 + tecnopor) × L entre zapatas
A7: Excavación vigas de conexión VC | B7: =SUMIF(Vigas_Cimentacion!B5:B26,"VC",Vigas_Cimentacion!N5:N26) -> 2.458125 | C7: b × 1.50 × L entre zapatas
A8: EXCAVACIÓN TOTAL | B8: =SUM(B5:B7) -> 89.086125
A9: (-) Solado | B9: =-Zapatas!J10*Parametros!$B$12 -> -4.6785 | C9: Área × 0.10
A10: (-) Concreto zapatas | B10: =-Zapatas!I10 -> -23.3925
A11: (-) Concreto vigas de cimentación | B11: =-Vigas_Cimentacion!J31 -> -7.66245 | C11: Incluye parte sobre zapatas
A12: (-) Tecnopor bajo VE | B12: =-Vigas_Cimentacion!L31*Parametros!$B$13 -> -0.73575
A13: (-) Columnas bajo NTN (-1.00 a ±0.00) | B13: =-Columnas!G16 -> -2.49
A14: RELLENO COMPACTADO CON MATERIAL PROPIO | B14: =SUM(B8:B13) -> 50.126925 | C14: Excavación - volumen de elementos
A15: Material excedente (en banco) | B15: =B8-B14 -> 38.9592
A16: Esponjamiento | B16: =Parametros!$B$9 -> 0.25 | C16: Parámetro
A17: ELIMINACIÓN DE MATERIAL EXCEDENTE (suelto) | B17: =B15*(1+B16) -> 48.699 | C17: Excedente × (1 + esponjamiento)

Sheet Insumos
A1: PRECIOS DE INSUMOS - Lima, octubre 2026 (referenciales, con IGV)
A2: AZUL = editable. Reemplazar por cotizaciones reales; todo el presupuesto se recalcula.
A4: Código | B4: Insumo | C4: Und | D4: Precio (S/) | E4: Fuente / supuesto
A5: b_op | B5: Jornal básico operario | C5: día | D5: 89.3 | E5: Tabla FTCCP-CAPECO 2026 (R.M. 197-2025-TR)
A6: b_of | B6: Jornal básico oficial | C6: día | D6: 69.75 | E6: Tabla FTCCP-CAPECO 2026
A7: b_pe | B7: Jornal básico peón | C7: día | D7: 62.8 | E7: Tabla FTCCP-CAPECO 2026
A8: ls | B8: Leyes y beneficios sociales sobre básico | C8: % | D8: 1.2 | E8: Supuesto típico (dominical, feriados, vacaciones, CTS, gratificaciones, EsSalud, SCTR, etc.)
A9: mov | B9: Movilidad acumulada | C9: día | D9: 8.6 | E9: Tabla 2026
A10: op | B10: Operario (costo hora-hombre) | C10: hh | D10: =(Insumos!$D$5*(1+Insumos!$D$8)+Insumos!$D$5*0.32+Insumos!$D$9)/8 -> 29.2045 | E10: (básico×(1+LS) + BUC 32% + movilidad)/8
A11: of | B11: Oficial (costo hora-hombre) | C11: hh | D11: =(Insumos!$D$6*(1+Insumos!$D$8)+Insumos!$D$6*0.3+Insumos!$D$9)/8 -> 22.871875 | E11: (básico×(1+LS) + BUC 30% + movilidad)/8
A12: pe | B12: Peón (costo hora-hombre) | C12: hh | D12: =(Insumos!$D$7*(1+Insumos!$D$8)+Insumos!$D$7*0.3+Insumos!$D$9)/8 -> 20.7 | E12: (básico×(1+LS) + BUC 30% + movilidad)/8
A13: c210 | B13: Concreto premezclado f'c 210 puesto en obra (mixer) | C13: m³ | D13: 380 | E13: Rango Lima 2026: S/ 260-415/m³ (concreteras.pe). Cotizar UNICON/Firth/Mixercon/Supermix
A14: bomba | B14: Servicio de bomba de concreto | C14: m³ | D14: 40 | E14: S/ 35-40/m³, mínimo facturable 20 m³ por vaciado
A15: bmin | B15: Mínimo facturable bomba por vaciado | C15: m³ | D15: 20 | E15: Referencia concreteras.pe
A16: dconc | B16: Desperdicio de concreto | C16: % | D16: 0.03 | E16: Supuesto
A17: acero | B17: Acero corrugado fy 4200 (Aceros Arequipa) | C17: kg | D17: 3.6 | E17: Varilla 5/8" 9 m S/ 43-55 (≈ S/ 3.1-3.9/kg). Supuesto promedio
A18: dacero | B18: Desperdicio de acero | C18: % | D18: 0.05 | E18: Supuesto
A19: al16 | B19: Alambre negro N°16 | C19: kg | D19: 6.5 | E19: Supuesto mercado
A20: al8 | B20: Alambre negro N°8 | C20: kg | D20: 6 | E20: Supuesto mercado
A21: clavo | B21: Clavos para madera c/c 3" | C21: kg | D21: 6.5 | E21: Supuesto mercado
A22: madera | B22: Madera tornillo para encofrado | C22: p2 | D22: 6.5 | E22: Supuesto mercado
A23: cem | B23: Cemento Portland tipo I (42.5 kg) | C23: bls | D23: 31 | E23: Supuesto mercado
A24: horm | B24: Hormigón | C24: m³ | D24: 80 | E24: Supuesto mercado Lima
... A30: volq | B30: Volquete 15 m³ con botadero autorizado (por viaje) | C30: viaje | D30: 500 | E30: Ref. 12-18 m³: S/ 290-570 + IGV (cymchamana). Actualizar
A31: cvolq | B31: Capacidad útil volquete | C31: m³ | D31: 15
A32: plancha | B32: Plancha compactadora 4 HP | C32: día | D32: 150 | E32: Supuesto
A33: mezc | B33: Mezcladora de concreto 9-11 p³ | C33: día | D33: 100 | E33: Supuesto
A34: vibr | B34: Vibrador de concreto 4 HP | C34: día | D34: 80 | E34: Supuesto
A35: balde | B35: Ancho de zanja de vigas con cucharón de retro | C35: m | D35: 0.6 | E35: Cucharón 24". Las zanjas de VE (0.30) y VC (0.25) salen más anchas
A36: gg | B36: Gastos generales (si contrata a un tercero) | C36: % | D36: 0 | E36: 0% si administra la obra usted mismo; típico 10%
A37: util | B37: Utilidad (si contrata a un tercero) | C37: % | D37: 0 | E37: 0% si administra usted; típico 8-10%

Sheet APU
A1: ANÁLISIS DE PRECIOS UNITARIOS
A2: Mano de obra: cantidad = cuadrilla × 8 / rendimiento. Precios con IGV desde la hoja Insumos.
A4: Excavación con retroexcavadora y perfilado manual de fondo | B4: m³
A5: Rendimiento (und/día) | B5: 40
A6: Recurso | B6: Und | C6: Cuadrilla | D6: Cantidad | E6: Precio (S/) | F6: Parcial (S/)
A7: Peón (perfilado, nivelación de fondo) | B7: hh | C7: 1 | D7: =C7*8/$B$5 -> 0.2 | E7: =Insumos!$D$12 -> 20.7 | F7: =D7*E7 -> 4.14
A8: Retroexcavadora con operador | B8: h | D8: =1/Insumos!$D$28 -> 0.083333333 | E8: =Insumos!$D$27 -> 170 | F8: =D8*E8 -> 14.166667
A9: Herramientas manuales (% MO) | B9: %MO | D9: 0.03 | E9: =SUM(F7) -> 4.14 | F9: =D9*E9 -> 0.1242
A10: COSTO UNITARIO | F10: =SUM(F7:F9) -> 18.430867
A12: Relleno compactado con material propio (capas 0.20, plancha) | B12: m³
A13: Rendimiento (und/día) | B13: 12
A14: Recurso | B14: Und | C14: Cuadrilla | D14: Cantidad | E14: Precio (S/) | F14: Parcial (S/)
A15: Oficial | B15: hh | C15: 1 | D15: =C15*8/$B$13 -> 0.66666667 | E15: =Insumos!$D$11 -> 22.871875 | F15: =D15*E15 -> 15.247917
A16: Peón | B16: hh | C16: 3 | D16: =C16*8/$B$13 -> 2 | E16: =Insumos!$D$12 -> 20.7 | F16: =D16*E16 -> 41.4
A17: Agua | B17: m³ | D17: 0.1 | E17: =Insumos!$D$25 -> 6 | F17: =D17*E17 -> 0.6
A18: Plancha compactadora | B18: día | D18: =1/$B$13 -> 0.083333333 | E18: =Insumos!$D$32 -> 150 | F18: =D18*E18 -> 12.5
A19: Herramientas manuales (% MO) | B19: %MO | D19: 0.03 | E19: =SUM(F15,F16) -> 56.647917 | F19: =D19*E19 -> 1.6994375
A20: COSTO UNITARIO | F20: =SUM(F15:F19) -> 71.447354
A22: Eliminación de material excedente (carguío con retro + volquete) | B22: viaje
A23: Rendimiento (und/día) | B23: 1
A24: Recurso | B24: Und | C24: Cuadrilla | D24: Cantidad | E24: Precio (S/) | F24: Parcial (S/)
A25: Volquete 15 m³ con botadero | B25: viaje | D25: 1 | E25: =Insumos!$D$30 -> 500 | F25: =D25*E25 -> 500
A26: Retroexcavadora carguío | B26: h | D26: =Insumos!$D$31/(2*Insumos!$D$28) -> 0.625 | E26: =Insumos!$D$27 -> 170 | F26: =D26*E26 -> 106.25
A27: COSTO UNITARIO | F27: =SUM(F25:F26) -> 606.25
A29: Solado C:H 1:12, e = 0.10 m (mezcladora) | B29: m²
A30: Rendimiento (und/día) | B30: 100
A31: Recurso | B31: Und | C31: Cuadrilla | D31: Cantidad | E31: Precio (S/) | F31: Parcial (S/)
A32: Operario | B32: hh | C32: 1 | D32: =C32*8/$B$30 -> 0.08 | E32: =Insumos!$D$10 -> 29.2045 | F32: =D32*E32 -> 2.33636
A33: Oficial | B33: hh | C33: 1 | D33: =C33*8/$B$30 -> 0.08 | E33: =Insumos!$D$11 -> 22.871875 | F33: =D33*E33 -> 1.82975
A34: Peón | B34: hh | C34: 4 | D34: =C34*8/$B$30 -> 0.32 | E34: =Insumos!$D$12 -> 20.7 | F34: =D34*E34 -> 6.624
A35: Cemento Portland tipo I | B35: bls | D35: 0.3 | E35: =Insumos!$D$23 -> 31 | F35: =D35*E35 -> 9.3
A36: Hormigón | B36: m³ | D36: 0.13 | E36: =Insumos!$D$24 -> 80 | F36: =D36*E36 -> 10.4
A37: Agua | B37: m³ | D37: 0.02 | E37: =Insumos!$D$25 -> 6 | F37: =D37*E37 -> 0.12
A38: Mezcladora 9-11 p³ | B38: día | D38: =1/$B$30 -> 0.01 | E38: =Insumos!$D$33 -> 100 | F38: =D38*E38 -> 1
A39: Herramientas manuales (% MO) | B39: %MO | D39: 0.03 | E39: =SUM(F32,F33,F34) -> 10.79011 | F39: =D39*E39 -> 0.3237033
A40: COSTO UNITARIO | F40: =SUM(F32:F39) -> 31.933813
A42: Concreto premezclado f'c 210 en zapatas y vigas de cimentación (mixer + bomba) | B42: m³
A43: Rendimiento (und/día) | B43: 30
A44: Recurso | B44: Und | C44: Cuadrilla | D44: Cantidad | E44: Precio (S/) | F44: Parcial (S/)
A45: Operario | B45: hh | C45: 1 | D45: =C45*8/$B$43 -> 0.26666667 | E45: =Insumos!$D$10 -> 29.2045 | F45: =D45*E45 -> 7.7878667
...
